<mujoco model="h1">
  <compiler angle="radian" meshdir="/root/.cache/robot_descriptions/mujoco_menagerie/unitree_h1/assets/"/>

  <statistic meansize="0.05"/>

  <default>
    <default class="h1">
      <joint armature="0.1" damping="1"/>
      <site size="0.001 0.005 0.005" group="4" rgba="0.5 0.5 0.5 0.3"/>
      <default class="visual">
        <geom type="mesh" contype="0" conaffinity="0" group="2" material="black"/>
      </default>
      <default class="collision">
        <geom group="3"/>
        <default class="foot">
          <geom size="0.014 0 0" type="capsule"/>
          <default class="foot1"/>
          <default class="foot2"/>
          <default class="foot3"/>
        </default>
      </default>
    </default>
  </default>

  <asset>
    <material name="black" rgba="0.1 0.1 0.1 1"/>
    <material name="white"/>
    <mesh name="pelvis" file="pelvis.stl"/>
    <mesh name="left_hip_yaw_link" file="left_hip_yaw_link.stl"/>
    <mesh name="left_hip_roll_link" file="left_hip_roll_link.stl"/>
    <mesh name="left_hip_pitch_link" file="left_hip_pitch_link.stl"/>
    <mesh name="left_knee_link" file="left_knee_link.stl"/>
    <mesh name="left_ankle_link" file="left_ankle_link.stl"/>
    <mesh name="right_hip_yaw_link" file="right_hip_yaw_link.stl"/>
    <mesh name="right_hip_roll_link" file="right_hip_roll_link.stl"/>
    <mesh name="right_hip_pitch_link" file="right_hip_pitch_link.stl"/>
    <mesh name="right_knee_link" file="right_knee_link.stl"/>
    <mesh name="right_ankle_link" file="right_ankle_link.stl"/>
    <mesh name="torso_link" file="torso_link.stl"/>
    <mesh name="left_shoulder_pitch_link" file="left_shoulder_pitch_link.stl"/>
    <mesh name="left_shoulder_roll_link" file="left_shoulder_roll_link.stl"/>
    <mesh name="left_shoulder_yaw_link" file="left_shoulder_yaw_link.stl"/>
    <mesh name="left_elbow_link" file="left_elbow_link.stl"/>
    <mesh name="right_shoulder_pitch_link" file="right_shoulder_pitch_link.stl"/>
    <mesh name="right_shoulder_roll_link" file="right_shoulder_roll_link.stl"/>
    <mesh name="right_shoulder_yaw_link" file="right_shoulder_yaw_link.stl"/>
    <mesh name="right_elbow_link" file="right_elbow_link.stl"/>
    <mesh name="logo_link" file="logo_link.stl"/>
  </asset>

  <worldbody>
    <light target="torso_link" pos="2 0 2.5" dir="0 0 -1" mode="targetbodycom"/>
    <body name="pelvis" childclass="h1" pos="0 0 1.06">
      <inertial pos="-0.0002 4e-05 -0.04522" quat="0.498303 0.499454 -0.500496 0.501741" mass="5.39" diaginertia="0.0490211 0.0445821 0.00824619"/>
      <joint type="free" limited="false" actuatorfrclimited="false" armature="0" damping="0"/>
      <geom class="visual" mesh="pelvis"/>
      <body name="left_hip_yaw_link" pos="0 0.0875 -0.1742">
        <inertial pos="-0.04923 0.0001 0.0072" quat="0.69699 0.219193 0.233287 0.641667" mass="2.244" diaginertia="0.00304494 0.00296885 0.00189201"/>
        <joint name="left_hip_yaw" pos="0 0 0" axis="0 0 1" range="-0.43 0.43"/>
        <geom class="visual" mesh="left_hip_yaw_link"/>
        <geom class="collision" size="0.06 0.035" pos="-0.067 0 0" quat="0.707123 0 0.70709 0" type="cylinder"/>
        <body name="left_hip_roll_link" pos="0.039468 0 0">
          <inertial pos="-0.0058 -0.00319 -9e-05" quat="0.0438242 0.70721 -0.0729075 0.701867" mass="2.232" diaginertia="0.00243264 0.00225325 0.00205492"/>
          <joint name="left_hip_roll" pos="0 0 0" axis="1 0 0" range="-0.43 0.43"/>
          <geom class="visual" mesh="left_hip_roll_link"/>
          <geom class="collision" size="0.05 0.03" pos="0 -0.02 0" quat="0.707107 0.707107 0 0" type="cylinder"/>
          <body name="left_hip_pitch_link" pos="0 0.11536 0">
            <inertial pos="0.00746 -0.02346 -0.08193" quat="0.979828 0.0513522 -0.0169854 -0.192382" mass="4.152" diaginertia="0.0829503 0.0821457 0.00510909"/>
            <joint name="left_hip_pitch" pos="0 0 0" axis="0 1 0" range="-1.57 1.57"/>
            <geom class="visual" mesh="left_hip_pitch_link"/>
            <geom class="collision" size="0.03 0.21095" pos="0 0 -0.19" quat="0.047458 0 0.998873 0" type="capsule"/>
            <geom class="collision" size="0.03 0.21" pos="0.02 0 -0.19" quat="0 1 0 0" type="capsule"/>
            <geom class="collision" size="0.05 0.02" pos="0 -0.07 0" quat="0.707107 0.707107 0 0" type="cylinder"/>
            <body name="left_knee_link" pos="0 0 -0.4">
              <inertial pos="-0.00136 -0.00512 -0.1384" quat="0.626132 -0.034227 -0.0416277 0.777852" mass="1.721" diaginertia="0.0125237 0.0123104 0.0019428"/>
              <joint name="left_knee" pos="0 0 0" axis="0 1 0" range="-0.26 2.05"/>
              <geom class="visual" mesh="left_knee_link"/>
              <geom class="collision" size="0.025 0.2" pos="0.02 0 -0.2" quat="0 1 0 0" type="capsule"/>
              <geom class="collision" size="0.05" pos="0 0 -0.115"/>
              <body name="left_ankle_link" pos="0 0 -0.4">
                <inertial pos="0.06722 0.00015 -0.04497" quat="0.489101 0.503197 0.565782 0.432972" mass="0.446" diaginertia="0.00220848 0.00218961 0.000214202"/>
                <joint name="left_ankle" pos="0 0 0" axis="0 1 0" range="-0.87 0.52"/>
                <geom class="visual" mesh="left_ankle_link"/>
                <geom class="foot1" size="0.014 0.0280446" pos="-0.0075 0 -0.0505" quat="0.633989 0 -0.773342 0"/>
                <geom class="foot2" size="0.014 0.0478174" pos="0.0675 0 -0.0505" quat="0.746666 0 -0.665199 0"/>
                <geom class="foot3" size="0.014 0.03" pos="0.14 0 -0.056" quat="0.707107 0.707107 0 0"/>
              </body>
            </body>
          </body>
        </body>
      </body>
      <body name="right_hip_yaw_link" pos="0 -0.0875 -0.1742">
        <inertial pos="-0.04923 -0.0001 0.0072" quat="0.641667 0.233287 0.219193 0.69699" mass="2.244" diaginertia="0.00304494 0.00296885 0.00189201"/>
        <joint name="right_hip_yaw" pos="0 0 0" axis="0 0 1" range="-0.43 0.43"/>
        <geom class="visual" mesh="right_hip_yaw_link"/>
        <geom class="collision" size="0.06 0.035" pos="-0.067 0 0" quat="0.707123 0 0.70709 0" type="cylinder"/>
        <body name="right_hip_roll_link" pos="0.039468 0 0">
          <inertial pos="-0.0058 0.00319 -9e-05" quat="-0.0438242 0.70721 0.0729075 0.701867" mass="2.232" diaginertia="0.00243264 0.00225325 0.00205492"/>
          <joint name="right_hip_roll" pos="0 0 0" axis="1 0 0" range="-0.43 0.43"/>
          <geom class="visual" mesh="right_hip_roll_link"/>
          <geom class="collision" size="0.05 0.03" pos="0 0.02 0" quat="0.707107 0.707107 0 0" type="cylinder"/>
          <body name="right_hip_pitch_link" pos="0 -0.11536 0">
            <inertial pos="0.00746 0.02346 -0.08193" quat="0.979828 -0.0513522 -0.0169854 0.192382" mass="4.152" diaginertia="0.0829503 0.0821457 0.00510909"/>
            <joint name="right_hip_pitch" pos="0 0 0" axis="0 1 0" range="-1.57 1.57"/>
            <geom class="visual" mesh="right_hip_pitch_link"/>
            <geom class="collision" size="0.03 0.21095" pos="0 0 -0.19" quat="0.047458 0 0.998873 0" type="capsule"/>
            <geom class="collision" size="0.03 0.21" pos="0.02 0 -0.19" quat="0 1 0 0" type="capsule"/>
            <geom class="collision" size="0.05 0.02" pos="0 0.07 0" quat="0.707107 0.707107 0 0" type="cylinder"/>
            <body name="right_knee_link" pos="0 0 -0.4">
              <inertial pos="-0.00136 0.00512 -0.1384" quat="0.777852 -0.0416277 -0.034227 0.626132" mass="1.721" diaginertia="0.0125237 0.0123104 0.0019428"/>
              <joint name="right_knee" pos="0 0 0" axis="0 1 0" range="-0.26 2.05"/>
              <geom class="visual" mesh="right_knee_link"/>
              <geom class="collision" size="0.025 0.2" pos="0.02 0 -0.2" quat="0 1 0 0" type="capsule"/>
              <geom class="collision" size="0.05" pos="0 0 -0.115"/>
              <body name="right_ankle_link" pos="0 0 -0.4">
                <inertial pos="0.06722 -0.00015 -0.04497" quat="0.432972 0.565782 0.503197 0.489101" mass="0.446" diaginertia="0.00220848 0.00218961 0.000214202"/>
                <joint name="right_ankle" pos="0 0 0" axis="0 1 0" range="-0.87 0.52"/>
                <geom class="visual" mesh="right_ankle_link"/>
                <geom class="foot1" size="0.014 0.0280446" pos="-0.0075 0 -0.0505" quat="0.633989 0 -0.773342 0"/>
                <geom class="foot2" size="0.014 0.0478174" pos="0.0675 0 -0.0505" quat="0.746666 0 -0.665199 0"/>
                <geom class="foot3" size="0.014 0.03" pos="0.14 0 -0.056" quat="0.707107 0.707107 0 0"/>
              </body>
            </body>
          </body>
        </body>
      </body>
      <body name="torso_link">
        <inertial pos="0.000489 0.002797 0.20484" quat="0.999989 -0.00130808 -0.00282289 -0.00349105" mass="17.789" diaginertia="0.487315 0.409628 0.127837"/>
        <joint name="torso" pos="0 0 0" axis="0 0 1" range="-2.35 2.35"/>
        <geom class="visual" mesh="torso_link"/>
        <geom class="visual" material="white" mesh="logo_link"/>
        <geom name="head" class="collision" size="0.06 0.04" pos="0.05 0 0.64" type="capsule"/>
        <geom name="helmet" class="collision" size="0.073" pos="0.045 0 0.68"/>
        <geom name="torso" class="collision" size="0.07 0.1 0.22" pos="0 0 0.25" type="box"/>
        <geom name="hip" class="collision" size="0.05 0.1" pos="0 0 -0.05" quat="0.707107 0.707107 0 0" type="capsule"/>
        <site name="imu" pos="-0.04452 -0.01891 0.27756"/>
        <body name="left_shoulder_pitch_link" pos="0.0055 0.15535 0.42999" quat="0.976296 0.216438 0 0">
          <inertial pos="0.005045 0.053657 -0.015715" quat="0.814858 0.579236 -0.0201072 -0.00936488" mass="1.033" diaginertia="0.00129936 0.000987113 0.000858198"/>
          <joint name="left_shoulder_pitch" pos="0 0 0" axis="0 1 0" range="-2.87 2.87"/>
          <geom class="visual" mesh="left_shoulder_pitch_link"/>
          <body name="left_shoulder_roll_link" pos="-0.0055 0.0565 -0.0165" quat="0.976296 -0.216438 0 0">
            <inertial pos="0.000679 0.00115 -0.094076" quat="0.732491 0.00917179 0.0766656 0.676384" mass="0.793" diaginertia="0.00170388 0.00158256 0.00100336"/>
            <joint name="left_shoulder_roll" pos="0 0 0" axis="1 0 0" range="-0.34 3.11"/>
            <geom class="visual" mesh="left_shoulder_roll_link"/>
            <geom name="left_shoulder" class="collision" size="0.04 0.0423792" pos="0 -0.03 -0.006" quat="0.815583 -0.57864 0 0" type="capsule"/>
            <body name="left_shoulder_yaw_link" pos="0 0 -0.1343">
              <inertial pos="0.01365 0.002767 -0.16266" quat="0.703042 -0.0331229 -0.0473362 0.708798" mass="0.839" diaginertia="0.00408038 0.00370367 0.000622687"/>
              <joint name="left_shoulder_yaw" pos="0 0 0" axis="0 0 1" range="-1.3 4.45"/>
              <geom class="visual" mesh="left_shoulder_yaw_link"/>
              <geom class="collision" size="0.03 0.175" pos="0 0 -0.025" type="capsule"/>
              <body name="left_elbow_link" pos="0.0185 0 -0.198">
                <inertial pos="0.15908 -0.000144 -0.015776" quat="0.0765232 0.720327 0.0853116 0.684102" mass="0.669" diaginertia="0.00601829 0.00600579 0.000408305"/>
                <joint name="left_elbow" pos="0 0 0" axis="0 1 0" range="-1.25 2.61"/>
                <geom class="visual" mesh="left_elbow_link"/>
                <geom class="collision" size="0.025 0.140201" pos="0.14 0 -0.0075" quat="0.725774 0 -0.687934 0" type="capsule"/>
                <geom class="collision" size="0.033" pos="0.28 0 -0.015"/>
                <body name="left_hand" pos="0.26 0 -0.025"/>
              </body>
              <body name="left_elbow_center" pos="-0.05 0 -0.2"/>
            </body>
          </body>
        </body>
        <body name="right_shoulder_pitch_link" pos="0.0055 -0.15535 0.42999" quat="0.976296 -0.216438 0 0">
          <inertial pos="0.005045 -0.053657 -0.015715" quat="0.579236 0.814858 0.00936488 0.0201072" mass="1.033" diaginertia="0.00129936 0.000987113 0.000858198"/>
          <joint name="right_shoulder_pitch" pos="0 0 0" axis="0 1 0" range="-2.87 2.87"/>
          <geom class="visual" mesh="right_shoulder_pitch_link"/>
          <body name="right_shoulder_roll_link" pos="-0.0055 -0.0565 -0.0165" quat="0.976296 0.216438 0 0">
            <inertial pos="0.000679 -0.00115 -0.094076" quat="0.676384 0.0766656 0.00917179 0.732491" mass="0.793" diaginertia="0.00170388 0.00158256 0.00100336"/>
            <joint name="right_shoulder_roll" pos="0 0 0" axis="1 0 0" range="-3.11 0.34"/>
            <geom class="visual" mesh="right_shoulder_roll_link"/>
            <geom name="right_shoulder" class="collision" size="0.04 0.0423792" pos="0 0.03 -0.006" quat="0.815583 0.57864 0 0" type="capsule"/>
            <body name="right_shoulder_yaw_link" pos="0 0 -0.1343">
              <inertial pos="0.01365 -0.002767 -0.16266" quat="0.708798 -0.0473362 -0.0331229 0.703042" mass="0.839" diaginertia="0.00408038 0.00370367 0.000622687"/>
              <joint name="right_shoulder_yaw" pos="0 0 0" axis="0 0 1" range="-4.45 1.3"/>
              <geom class="visual" mesh="right_shoulder_yaw_link"/>
              <geom class="collision" size="0.03 0.175" pos="0 0 -0.025" type="capsule"/>
              <body name="right_elbow_link" pos="0.0185 0 -0.198">
                <inertial pos="0.15908 0.000144 -0.015776" quat="-0.0765232 0.720327 -0.0853116 0.684102" mass="0.669" diaginertia="0.00601829 0.00600579 0.000408305"/>
                <joint name="right_elbow" pos="0 0 0" axis="0 1 0" range="-1.25 2.61"/>
                <geom class="visual" mesh="right_elbow_link"/>
                <geom class="collision" size="0.025 0.140201" pos="0.14 0 -0.0075" quat="0.725774 0 -0.687934 0" type="capsule"/>
                <geom class="collision" size="0.033" pos="0.28 0 -0.015"/>
                <body name="right_hand" pos="0.26 0 -0.025"/>
              </body>
              <body name="right_elbow_center" pos="-0.05 0 -0.2"/>
            </body>
          </body>
        </body>
        <body name="torso_center" pos="0 0 0.4"/>
        <body name="torso_middle" pos="0 0 0.2"/>
        <body name="spine" pos="0 0 0.17"/>
      </body>
    </body>
  </worldbody>

  <contact>
    <exclude body1="torso_link" body2="left_shoulder_roll_link"/>
    <exclude body1="torso_link" body2="right_shoulder_roll_link"/>
  </contact>

  <actuator>
    <general name="left_hip_yaw" class="h1" joint="left_hip_yaw" ctrlrange="-200 200"/>
    <general name="left_hip_roll" class="h1" joint="left_hip_roll" ctrlrange="-200 200"/>
    <general name="left_hip_pitch" class="h1" joint="left_hip_pitch" ctrlrange="-200 200"/>
    <general name="left_knee" class="h1" joint="left_knee" ctrlrange="-300 300"/>
    <general name="left_ankle" class="h1" joint="left_ankle" ctrlrange="-40 40"/>
    <general name="right_hip_yaw" class="h1" joint="right_hip_yaw" ctrlrange="-200 200"/>
    <general name="right_hip_roll" class="h1" joint="right_hip_roll" ctrlrange="-200 200"/>
    <general name="right_hip_pitch" class="h1" joint="right_hip_pitch" ctrlrange="-200 200"/>
    <general name="right_knee" class="h1" joint="right_knee" ctrlrange="-300 300"/>
    <general name="right_ankle" class="h1" joint="right_ankle" ctrlrange="-40 40"/>
    <general name="torso" class="h1" joint="torso" ctrlrange="-200 200"/>
    <general name="left_shoulder_pitch" class="h1" joint="left_shoulder_pitch" ctrlrange="-40 40"/>
    <general name="left_shoulder_roll" class="h1" joint="left_shoulder_roll" ctrlrange="-40 40"/>
    <general name="left_shoulder_yaw" class="h1" joint="left_shoulder_yaw" ctrlrange="-18 18"/>
    <general name="left_elbow" class="h1" joint="left_elbow" ctrlrange="-18 18"/>
    <general name="right_shoulder_pitch" class="h1" joint="right_shoulder_pitch" ctrlrange="-40 40"/>
    <general name="right_shoulder_roll" class="h1" joint="right_shoulder_roll" ctrlrange="-40 40"/>
    <general name="right_shoulder_yaw" class="h1" joint="right_shoulder_yaw" ctrlrange="-18 18"/>
    <general name="right_elbow" class="h1" joint="right_elbow" ctrlrange="-18 18"/>
  </actuator>
</mujoco>
