<mujoco model="Hi">
  <compiler angle="radian" meshdir="/home/jeff/Codes/Robots/install/motion_retargeting/share/motion_retargeting/../../../../src/motion_retargeting/robots/hi_1/urdf/../meshes/"/>

  <size njmax="500" nconmax="100"/>

  <asset>
    <mesh name="SACRUM" file="SACRUM.STL"/>
    <mesh name="TORSO" file="TORSO.STL"/>
    <mesh name="SCAPULA_R" file="SCAPULA_R.STL"/>
    <mesh name="SHOULDER_R" file="SHOULDER_R.STL"/>
    <mesh name="UPPERARM_R" file="UPPERARM_R.STL"/>
    <mesh name="FOREARM_R" file="FOREARM_R.STL"/>
    <mesh name="WRIST_REVOLUTE_R" file="WRIST_REVOLUTE_R.STL"/>
    <mesh name="WRIST_UPDOWN_R" file="WRIST_UPDOWN_R.STL"/>
    <mesh name="HAND_R" file="HAND_R.STL"/>
    <mesh name="SCAPULA_L" file="SCAPULA_L.STL"/>
    <mesh name="SHOULDER_L" file="SHOULDER_L.STL"/>
    <mesh name="UPPERARM_L" file="UPPERARM_L.STL"/>
    <mesh name="FOREARM_L" file="FOREARM_L.STL"/>
    <mesh name="WRIST_REVOLUTE_L" file="WRIST_REVOLUTE_L.STL"/>
    <mesh name="WRIST_UPDOWN_L" file="WRIST_UPDOWN_L.STL"/>
    <mesh name="HAND_L" file="HAND_L.STL"/>
    <mesh name="ILIUM_R" file="ILIUM_R.STL"/>
    <mesh name="ISCHIUM_R" file="ISCHIUM_R.STL"/>
    <mesh name="THIGH_R" file="THIGH_R.STL"/>
    <mesh name="SHANK_R" file="SHANK_R.STL"/>
    <mesh name="ASTRAGALUS_R" file="ASTRAGALUS_R.STL"/>
    <mesh name="FOOT_R" file="FOOT_R.STL"/>
    <mesh name="ILIUM_L" file="ILIUM_L.STL"/>
    <mesh name="ISCHIUM_L" file="ISCHIUM_L.STL"/>
    <mesh name="THIGH_L" file="THIGH_L.STL"/>
    <mesh name="SHANK_L" file="SHANK_L.STL"/>
    <mesh name="ASTRAGALUS_L" file="ASTRAGALUS_L.STL"/>
    <mesh name="FOOT_L" file="FOOT_L.STL"/>
    <mesh name="NECK" file="NECK.STL"/>
    <mesh name="HEAD" file="HEAD.STL"/>
  </asset>

  <worldbody>
    <body name="TORSO" pos="0 0 0.755">
      <joint name="float_base" type="free"/>
      <geom type="mesh" contype="0" conaffinity="0" group="1" rgba="0.49804 0.49804 0.49804 1" mesh="TORSO"/>
      <geom type="mesh" rgba="0.49804 0.49804 0.49804 1" mesh="TORSO"/>
      <geom pos="0 0 0.43204" type="mesh" contype="0" conaffinity="0" group="1" rgba="0.69804 0.69804 0.69804 1" mesh="NECK"/>
      <geom pos="0 0 0.43204" type="mesh" rgba="0.69804 0.69804 0.69804 1" mesh="NECK"/>
      <geom pos="0 0 0.47404" quat="1 0 0 0" type="mesh" contype="0" conaffinity="0" group="1" rgba="0.38431 0.41176 0.45098 1" mesh="HEAD"/>
      <geom pos="0 0 0.47404" quat="1 0 0 0" type="mesh" rgba="0.38431 0.41176 0.45098 1" mesh="HEAD"/>
      <body name="SACRUM" pos="0 0 -0.0691">
        <inertial pos="0.000349547 6.72204e-06 -0.0507128" quat="0.5 0.5 -0.5 0.5" mass="3.02216" diaginertia="0.011 0.01 0.004"/>
        <joint name="A_Waist" pos="0 0 0" axis="0 0 1" limited="true" range="-0.523 0.523"/>
        <geom type="mesh" contype="0" conaffinity="0" group="1" rgba="0.498039 0.498039 0.498039 1" mesh="SACRUM"/>
        <geom type="mesh" rgba="0.498039 0.498039 0.498039 1" mesh="SACRUM"/>
        <body name="ILIUM_R" pos="0 -0.051 -0.1698">
          <inertial pos="-0.0975643 -0.0354786 0.00831189" quat="0.345088 0.717667 0.381592 0.469315" mass="2.81278" diaginertia="0.0123078 0.0115244 0.00516779"/>
          <joint name="Hip_Z_R" pos="0 0 0" axis="0 0 1" limited="true" range="-0.209 0.209"/>
          <geom type="mesh" contype="0" conaffinity="0" group="1" rgba="0.439216 0.439216 0.439216 1" mesh="ILIUM_R"/>
          <geom type="mesh" rgba="0.439216 0.439216 0.439216 1" mesh="ILIUM_R"/>
          <body name="ISCHIUM_R" pos="0 -0.0375 0">
            <inertial pos="-0.00365073 0.01867 -0.000208503" quat="0.5 0.5 0.5 0.5" mass="2.53761" diaginertia="0.005 0.004 0.003"/>
            <joint name="Hip_X_R" pos="0 0 0" axis="1 0 0" limited="true" range="-0.436 0.436"/>
            <geom type="mesh" contype="0" conaffinity="0" group="1" rgba="0.792157 0.819608 0.933333 1" mesh="ISCHIUM_R"/>
            <geom type="mesh" rgba="0.792157 0.819608 0.933333 1" mesh="ISCHIUM_R"/>
            <body name="THIGH_R" pos="0 -0.043004 0">
              <inertial pos="0.00489161 -0.0230655 -0.0408628" quat="0.49164 0.227122 -0.332054 0.772299" mass="2.94366" diaginertia="0.0202135 0.0202135 0.0202135"/>
              <joint name="Hip_Y_R" pos="0 0 0" axis="0 1 0" limited="true" range="-2.443 0.436"/>
              <geom type="mesh" contype="0" conaffinity="0" group="1" rgba="1 1 1 1" mesh="THIGH_R"/>
              <geom type="mesh" rgba="1 1 1 1" mesh="THIGH_R"/>
              <body name="SHANK_R" pos="0 0 -0.34">
                <inertial pos="0.011081 -0.00748588 -0.071984" quat="0.706836 -0.0195591 0.0195591 0.706836" mass="2.27928" diaginertia="0.0200554 0.02 0.00194461"/>
                <joint name="Knee_R" pos="0 0 0" axis="0 1 0" limited="true" range="0.2 2.443"/>
                <geom type="mesh" contype="0" conaffinity="0" group="1" rgba="0.898039 0.917647 0.929412 1" mesh="SHANK_R"/>
                <geom type="mesh" rgba="0.898039 0.917647 0.929412 1" mesh="SHANK_R"/>
                <geom size="0.05 0.1" pos="0.035 0 -0.18" type="cylinder" rgba="0.898039 0.917647 0.929412 1"/>
                <body name="ASTRAGALUS_R" pos="0 0 -0.36">
                  <inertial pos="0.00246209 5.9176e-05 1.23145e-07" quat="2.16976e-06 0.707113 1.38988e-05 0.707101" mass="0.0540428" diaginertia="8.59959e-06 7.67426e-06 4.09614e-06"/>
                  <joint name="Ankle_Y_R" pos="0 0 0" axis="0 1 0" limited="true" range="-0.698 0.525"/>
                  <geom type="mesh" contype="0" conaffinity="0" group="1" rgba="0.529412 0.54902 0.54902 1" mesh="ASTRAGALUS_R"/>
                  <geom type="mesh" rgba="0.529412 0.54902 0.54902 1" mesh="ASTRAGALUS_R"/>
                  <body name="FOOT_R">
                    <inertial pos="0.0172182 -0.000490155 -0.0526972" quat="0.5 0.5 0.5 0.5" mass="0.669214" diaginertia="0.002 0.002 0.001"/>
                    <joint name="Ankle_X_R" pos="0 0 0" axis="-1 0 0" limited="true" range="-0.331 0.331"/>
                    <geom type="mesh" contype="0" conaffinity="0" group="1" rgba="1 1 1 1" mesh="FOOT_R"/>
                    <geom type="mesh" rgba="1 1 1 1" mesh="FOOT_R"/>
                  </body>
                </body>
              </body>
            </body>
          </body>
        </body>
        <body name="ILIUM_L" pos="0 0.051 -0.1698">
          <inertial pos="-0.097564 0.035504 0.0082709" quat="0.469315 0.381592 0.717667 0.345088" mass="2.8128" diaginertia="0.0123078 0.0115244 0.00516779"/>
          <joint name="Hip_Z_L" pos="0 0 0" axis="0 0 1" limited="true" range="-0.209 0.209"/>
          <geom type="mesh" contype="0" conaffinity="0" group="1" rgba="0.89804 0.91765 0.92941 1" mesh="ILIUM_L"/>
          <geom type="mesh" rgba="0.89804 0.91765 0.92941 1" mesh="ILIUM_L"/>
          <body name="ISCHIUM_L" pos="0 0.0375 0">
            <inertial pos="-0.00378119 -0.018637 -0.000334509" quat="0.707107 0 0 0.707107" mass="2.54211" diaginertia="0.005 0.004 0.004"/>
            <joint name="Hip_X_L" pos="0 0 0" axis="1 0 0" limited="true" range="-0.436 0.436"/>
            <geom type="mesh" contype="0" conaffinity="0" group="1" rgba="0.898039 0.917647 0.929412 1" mesh="ISCHIUM_L"/>
            <geom type="mesh" rgba="0.898039 0.917647 0.929412 1" mesh="ISCHIUM_L"/>
            <body name="THIGH_L" pos="0 0.043004 0">
              <inertial pos="0.00486745 0.0229267 -0.0416365" quat="0.972296 0.010164 0.0430554 -0.229528" mass="2.95253" diaginertia="0.0301984 0.03 0.00480157"/>
              <joint name="Hip_Y_L" pos="0 0 0" axis="0 1 0" limited="true" range="-2.443 0.436"/>
              <geom type="mesh" contype="0" conaffinity="0" group="1" rgba="0.898039 0.917647 0.929412 1" mesh="THIGH_L"/>
              <geom type="mesh" rgba="0.898039 0.917647 0.929412 1" mesh="THIGH_L"/>
              <body name="SHANK_L" pos="0 0 -0.34">
                <inertial pos="0.0111438 0.00751442 -0.0718395" quat="0.706836 0.0195591 -0.0195591 0.706836" mass="2.28348" diaginertia="0.0200554 0.02 0.00194461"/>
                <joint name="Knee_L" pos="0 0 0" axis="0 1 0" limited="true" range="0.2 2.443"/>
                <geom type="mesh" contype="0" conaffinity="0" group="1" rgba="0.898039 0.917647 0.929412 1" mesh="SHANK_L"/>
                <geom type="mesh" rgba="0.898039 0.917647 0.929412 1" mesh="SHANK_L"/>
                <geom size="0.05 0.1" pos="0.035 0 -0.18" type="cylinder" rgba="0.898039 0.917647 0.929412 1"/>
                <body name="ASTRAGALUS_L" pos="0 0 -0.36">
                  <inertial pos="0.00246209 5.93317e-05 -1.23145e-07" quat="1.38988e-05 0.707101 2.16976e-06 0.707113" mass="0.0540428" diaginertia="8.59959e-06 7.67426e-06 4.09614e-06"/>
                  <joint name="Ankle_Y_L" pos="0 0 0" axis="0 1 0" limited="true" range="-0.698 0.525"/>
                  <geom type="mesh" contype="0" conaffinity="0" group="1" rgba="0.529412 0.54902 0.54902 1" mesh="ASTRAGALUS_L"/>
                  <geom type="mesh" rgba="0.529412 0.54902 0.54902 1" mesh="ASTRAGALUS_L"/>
                  <body name="FOOT_L">
                    <inertial pos="0.0173379 0.000446493 -0.0526985" quat="0.00111676 0.710224 -0.0108868 0.703891" mass="0.669298" diaginertia="0.00165364 0.00143915 0.000265397"/>
                    <joint name="Ankle_X_L" pos="0 0 0" axis="1 0 0" limited="true" range="-0.331 0.331"/>
                    <geom type="mesh" contype="0" conaffinity="0" group="1" rgba="0.792157 0.819608 0.933333 1" mesh="FOOT_L"/>
                    <geom type="mesh" rgba="0.792157 0.819608 0.933333 1" mesh="FOOT_L"/>
                  </body>
                </body>
              </body>
            </body>
          </body>
        </body>
      </body>
      <body name="SCAPULA_R" pos="0 -0.15869 0.29644" quat="0.984807 -0.17365 0 0">
        <inertial pos="0.00400567 -0.0697846 -0.000414012" mass="1.26951" diaginertia="0.001 0.001 0.001"/>
        <joint name="Shoulder_Y_R" pos="0 0 0" axis="0 1 0" limited="true" range="-3.14 1.22"/>
        <geom type="mesh" contype="0" conaffinity="0" group="1" rgba="0.698039 0.698039 0.698039 1" mesh="SCAPULA_R"/>
        <geom type="mesh" rgba="0.698039 0.698039 0.698039 1" mesh="SCAPULA_R"/>
        <body name="SHOULDER_R" pos="0 -0.075202 0" quat="0.984807 0.17365 0 0">
          <inertial pos="-0.000187388 -0.000796213 -0.0823834" quat="0.707107 0 0 0.707107" mass="1.38176" diaginertia="0.004 0.003 0.001"/>
          <joint name="Shoulder_X_R" pos="0 0 0" axis="1 0 0" limited="true" range="-2.26 0"/>
          <geom type="mesh" contype="0" conaffinity="0" group="1" rgba="0.698039 0.698039 0.698039 1" mesh="SHOULDER_R"/>
          <geom type="mesh" rgba="0.698039 0.698039 0.698039 1" mesh="SHOULDER_R"/>
          <body name="UPPERARM_R" pos="-1e-05 0 -0.0845">
            <inertial pos="-0.000150428 -0.00138375 -0.119529" mass="1.15168" diaginertia="0.003 0.003 0.001"/>
            <joint name="Shoulder_Z_R" pos="0 0 0" axis="0 0 1" limited="true" range="-2.09 2.09"/>
            <geom type="mesh" contype="0" conaffinity="0" group="1" rgba="0.898039 0.917647 0.929412 1" mesh="UPPERARM_R"/>
            <geom type="mesh" rgba="0.898039 0.917647 0.929412 1" mesh="UPPERARM_R"/>
            <body name="FOREARM_R" pos="0 0 -0.1455">
              <inertial pos="-0.000517598 0.000475828 -0.0750122" mass="0.964265" diaginertia="0.002 0.002 0.001"/>
              <joint name="Elbow_R" pos="0 0 0" axis="0 1 0" limited="true" range="-1.57 0"/>
              <geom type="mesh" contype="0" conaffinity="0" group="1" rgba="0.898039 0.917647 0.929412 1" mesh="FOREARM_R"/>
              <geom type="mesh" rgba="0.898039 0.917647 0.929412 1" mesh="FOREARM_R"/>
              <body name="WRIST_REVOLUTE_R" pos="0 0 -0.068424">
                <inertial pos="0.000431442 -0.000950549 -0.10525" mass="0.80708" diaginertia="0.003 0.002 0.001"/>
                <joint name="Wrist_Z_R" pos="0 0 0" axis="0 0 1" limited="true" range="-2.96 2.96"/>
                <geom type="mesh" contype="0" conaffinity="0" group="1" rgba="0.898039 0.917647 0.929412 1" mesh="WRIST_REVOLUTE_R"/>
                <geom type="mesh" rgba="0.898039 0.917647 0.929412 1" mesh="WRIST_REVOLUTE_R"/>
                <body name="WRIST_UPDOWN_R" pos="0 0 -0.20158">
                  <inertial pos="0.0012106 -0.000409146 -2.30693e-05" quat="0.720238 0.693722 -0.00126299 -0.00226084" mass="0.300586" diaginertia="7.19521e-05 4.61898e-05 4.18796e-05"/>
                  <joint name="Wrist_Y_R" pos="0 0 0" axis="0 1 0" limited="true" range="-0.87 0.87"/>
                  <geom type="mesh" contype="0" conaffinity="0" group="1" rgba="0.811765 1 0.980392 1" mesh="WRIST_UPDOWN_R"/>
                  <geom type="mesh" rgba="0.811765 1 0.980392 1" mesh="WRIST_UPDOWN_R"/>
                  <body name="HAND_R">
                    <inertial pos="0.00704233 -0.000160094 -0.123525" quat="0.706595 -0.00354027 -0.00304861 0.707603" mass="0.664607" diaginertia="0.002 0.002 0.002"/>
                    <joint name="Wrist_X_R" pos="0 0 0" axis="1 0 0" limited="true" range="-0.87 1.57"/>
                    <geom type="mesh" contype="0" conaffinity="0" group="1" rgba="0.898039 0.917647 0.929412 1" mesh="HAND_R"/>
                    <geom type="mesh" rgba="0.898039 0.917647 0.929412 1" mesh="HAND_R"/>
                  </body>
                </body>
              </body>
            </body>
          </body>
        </body>
      </body>
      <body name="SCAPULA_L" pos="0 0.15869 0.29644" quat="0.984807 0.17365 0 0">
        <inertial pos="0.00400264 0.069788 0.000251205" mass="1.2694" diaginertia="0.001 0.001 0.001"/>
        <joint name="Shoulder_Y_L" pos="0 0 0" axis="0 1 0" limited="true" range="-1.22 3.14"/>
        <geom type="mesh" contype="0" conaffinity="0" group="1" rgba="0.698039 0.698039 0.698039 1" mesh="SCAPULA_L"/>
        <geom type="mesh" rgba="0.698039 0.698039 0.698039 1" mesh="SCAPULA_L"/>
        <body name="SHOULDER_L" pos="0 0.075202 0" quat="0.984807 -0.17365 0 0">
          <inertial pos="-0.000181357 0.000167995 -0.0823677" quat="0.707107 0 0 0.707107" mass="1.38241" diaginertia="0.004 0.003 0.001"/>
          <joint name="Shoulder_X_L" pos="0 0 0" axis="1 0 0" limited="true" range="0 2.26"/>
          <geom type="mesh" contype="0" conaffinity="0" group="1" rgba="0.898039 0.917647 0.929412 1" mesh="SHOULDER_L"/>
          <geom type="mesh" rgba="0.898039 0.917647 0.929412 1" mesh="SHOULDER_L"/>
          <body name="UPPERARM_L" pos="0 0 -0.0845">
            <inertial pos="7.4844e-05 0.000973182 -0.119564" mass="1.15205" diaginertia="0.003 0.003 0.001"/>
            <joint name="Shoulder_Z_L" pos="0 0 0" axis="0 0 1" limited="true" range="-2.09 2.09"/>
            <geom type="mesh" contype="0" conaffinity="0" group="1" rgba="0.898039 0.917647 0.929412 1" mesh="UPPERARM_L"/>
            <geom type="mesh" rgba="0.898039 0.917647 0.929412 1" mesh="UPPERARM_L"/>
            <body name="FOREARM_L" pos="0 0 -0.1455">
              <inertial pos="-0.000538801 0.000598634 -0.0750634" mass="0.962924" diaginertia="0.002 0.002 0.001"/>
              <joint name="Elbow_L" pos="0 0 0" axis="0 1 0" limited="true" range="-1.57 0"/>
              <geom type="mesh" contype="0" conaffinity="0" group="1" rgba="0.898039 0.917647 0.929412 1" mesh="FOREARM_L"/>
              <geom type="mesh" rgba="0.898039 0.917647 0.929412 1" mesh="FOREARM_L"/>
              <body name="WRIST_REVOLUTE_L" pos="0 0 -0.068424">
                <inertial pos="0.000421442 0.000436044 -0.106092" mass="0.816183" diaginertia="0.003 0.003 0.001"/>
                <joint name="Wrist_Z_L" pos="0 0 0" axis="0 0 1" limited="true" range="-2.96 2.96"/>
                <geom type="mesh" contype="0" conaffinity="0" group="1" rgba="0.898039 0.917647 0.929412 1" mesh="WRIST_REVOLUTE_L"/>
                <geom type="mesh" rgba="0.898039 0.917647 0.929412 1" mesh="WRIST_REVOLUTE_L"/>
                <body name="WRIST_UPDOWN_L" pos="0 0 -0.20158">
                  <inertial pos="0.00121061 0.000367633 1.31576e-05" quat="0.694042 0.719933 0.000449513 0.00146278" mass="0.300587" diaginertia="7.1952e-05 4.61937e-05 4.18769e-05"/>
                  <joint name="Wrist_Y_L" pos="0 0 0" axis="0 1 0" limited="true" range="-0.87 0.87"/>
                  <geom type="mesh" contype="0" conaffinity="0" group="1" rgba="0.898039 0.917647 0.929412 1" mesh="WRIST_UPDOWN_L"/>
                  <geom type="mesh" rgba="0.898039 0.917647 0.929412 1" mesh="WRIST_UPDOWN_L"/>
                  <body name="HAND_L">
                    <inertial pos="0.00682932 -0.000266255 -0.123477" quat="0.707107 0 0 0.707107" mass="0.664798" diaginertia="0.003 0.002 0.001"/>
                    <joint name="Wrist_X_L" pos="0 0 0" axis="1 0 0" limited="true" range="-1.57 0.87"/>
                    <geom type="mesh" contype="0" conaffinity="0" group="1" rgba="0.898039 0.917647 0.929412 1" mesh="HAND_L"/>
                    <geom type="mesh" rgba="0.898039 0.917647 0.929412 1" mesh="HAND_L"/>
                  </body>
                </body>
              </body>
            </body>
          </body>
        </body>
      </body>
      <body name="torso_center" pos="0 0 0.25"/>
    </body>
  </worldbody>
</mujoco>
